Workbook

Sheet 1. Resumen
A1: FICHA DE CATEGORÍA · RESUMEN
A2: Se rellena solo a partir de las hojas 2 y 3. No escribas aquí.
A5: Categoría | B5: Responsable | C5: Objetivo del trimestre | D5: Presupuesto de surtido | E5: Última reunión | F5: Próxima revisión | G5: Aviso
A6: =IF('2. Ficha'!C5="","",'2. Ficha'!C5) | B6: =IF('2. Ficha'!C6="","",'2. Ficha'!C6) | C6: =IF('2. Ficha'!C7="","",'2. Ficha'!C7) | D6: =IF('2. Ficha'!C8="","",'2. Ficha'!C8) | E6: =IF($A6="","",IF(SUMPRODUCT(MAX(('3. Reuniones'!$B$5:$B$64=$A6)*('3. Reuniones'!$A$5:$A$64<>"")*'3. Reuniones'!$A$5:$A$64))=0,"",SUMPRODUCT(MAX(('3. Reuniones'!$B$5:$B$64=$A6)*('3. Reuniones'!$A$5:$A$64<>"")*'3. Reuniones'!$A$5:$A$64)))) | F6: =IF('2. Ficha'!C10="","",'2. Ficha'!C10) | G6: =IF($A6="","",IF($E6="","Sin reunión",IF(TODAY()-$E6>45,"Sin reunión",IF(AND($F6<>"",$F6<TODAY()),"Revisión vencida",""))))
A7: =IF('2. Ficha'!C15="","",'2. Ficha'!C15) | B7: =IF('2. Ficha'!C16="","",'2. Ficha'!C16) | C7: =IF('2. Ficha'!C17="","",'2. Ficha'!C17) | D7: =IF('2. Ficha'!C18="","",'2. Ficha'!C18) | E7: =IF($A7="","",IF(SUMPRODUCT(MAX(('3. Reuniones'!$B$5:$B$64=$A7)*('3. Reuniones'!$A$5:$A$64<>"")*'3. Reuniones'!$A$5:$A$64))=0,"",SUMPRODUCT(MAX(('3. Reuniones'!$B$5:$B$64=$A7)*('3. Reuniones'!$A$5:$A$64<>"")*'3. Reuniones'!$A$5:$A$64)))) | F7: =IF('2. Ficha'!C20="","",'2. Ficha'!C20) | G7: =IF($A7="","",IF($E7="","Sin reunión",IF(TODAY()-$E7>45,"Sin reunión",IF(AND($F7<>"",$F7<TODAY()),"Revisión vencida",""))))
A8: =IF('2. Ficha'!C25="","",'2. Ficha'!C25) | B8: =IF('2. Ficha'!C26="","",'2. Ficha'!C26) | C8: =IF('2. Ficha'!C27="","",'2. Ficha'!C27) | D8: =IF('2. Ficha'!C28="","",'2. Ficha'!C28) | E8: =IF($A8="","",IF(SUMPRODUCT(MAX(('3. Reuniones'!$B$5:$B$64=$A8)*('3. Reuniones'!$A$5:$A$64<>"")*'3. Reuniones'!$A$5:$A$64))=0,"",SUMPRODUCT(MAX(('3. Reuniones'!$B$5:$B$64=$A8)*('3. Reuniones'!$A$5:$A$64<>"")*'3. Reuniones'!$A$5:$A$64)))) | F8: =IF('2. Ficha'!C30="","",'2. Ficha'!C30) | G8: =IF($A8="","",IF($E8="","Sin reunión",IF(TODAY()-$E8>45,"Sin reunión",IF(AND($F8<>"",$F8<TODAY()),"Revisión vencida",""))))
A9: =IF('2. Ficha'!C35="","",'2. Ficha'!C35) | B9: =IF('2. Ficha'!C36="","",'2. Ficha'!C36) | C9: =IF('2. Ficha'!C37="","",'2. Ficha'!C37) | D9: =IF('2. Ficha'!C38="","",'2. Ficha'!C38) | E9: =IF($A9="","",IF(SUMPRODUCT(MAX(('3. Reuniones'!$B$5:$B$64=$A9)*('3. Reuniones'!$A$5:$A$64<>"")*'3. Reuniones'!$A$5:$A$64))=0,"",SUMPRODUCT(MAX(('3. Reuniones'!$B$5:$B$64=$A9)*('3. Reuniones'!$A$5:$A$64<>"")*'3. Reuniones'!$A$5:$A$64)))) | F9: =IF('2. Ficha'!C40="","",'2. Ficha'!C40) | G9: =IF($A9="","",IF($E9="","Sin reunión",IF(TODAY()-$E9>45,"Sin reunión",IF(AND($F9<>"",$F9<TODAY()),"Revisión vencida",""))))
A10: =IF('2. Ficha'!C45="","",'2. Ficha'!C45) | B10: =IF('2. Ficha'!C46="","",'2. Ficha'!C46) | C10: =IF('2. Ficha'!C47="","",'2. Ficha'!C47) | D10: =IF('2. Ficha'!C48="","",'2. Ficha'!C48) | E10: =IF($A10="","",IF(SUMPRODUCT(MAX(('3. Reuniones'!$B$5:$B$64=$A10)*('3. Reuniones'!$A$5:$A$64<>"")*'3. Reuniones'!$A$5:$A$64))=0,"",SUMPRODUCT(MAX(('3. Reuniones'!$B$5:$B$64=$A10)*('3. Reuniones'!$A$5:$A$64<>"")*'3. Reuniones'!$A$5:$A$64)))) | F10: =IF('2. Ficha'!C50="","",'2. Ficha'!C50) | G10: =IF($A10="","",IF($E10="","Sin reunión",IF(TODAY()-$E10>45,"Sin reunión",IF(AND($F10<>"",$F10<TODAY()),"Revisión vencida",""))))
A11: =IF('2. Ficha'!C55="","",'2. Ficha'!C55) | B11: =IF('2. Ficha'!C56="","",'2. Ficha'!C56) | C11: =IF('2. Ficha'!C57="","",'2. Ficha'!C57) | D11: =IF('2. Ficha'!C58="","",'2. Ficha'!C58) | E11: =IF($A11="","",IF(SUMPRODUCT(MAX(('3. Reuniones'!$B$5:$B$64=$A11)*('3. Reuniones'!$A$5:$A$64<>"")*'3. Reuniones'!$A$5:$A$64))=0,"",SUMPRODUCT(MAX(('3. Reuniones'!$B$5:$B$64=$A11)*('3. Reuniones'!$A$5:$A$64<>"")*'3. Reuniones'!$A$5:$A$64)))) | F11: =IF('2. Ficha'!C60="","",'2. Ficha'!C60) | G11: =IF($A11="","",IF($E11="","Sin reunión",IF(TODAY()-$E11>45,"Sin reunión",IF(AND($F11<>"",$F11<TODAY()),"Revisión vencida",""))))
A12: =IF('2. Ficha'!C65="","",'2. Ficha'!C65) | B12: =IF('2. Ficha'!C66="","",'2. Ficha'!C66) | C12: =IF('2. Ficha'!C67="","",'2. Ficha'!C67) | D12: =IF('2. Ficha'!C68="","",'2. Ficha'!C68) | E12: =IF($A12="","",IF(SUMPRODUCT(MAX(('3. Reuniones'!$B$5:$B$64=$A12)*('3. Reuniones'!$A$5:$A$64<>"")*'3. Reuniones'!$A$5:$A$64))=0,"",SUMPRODUCT(MAX(('3. Reuniones'!$B$5:$B$64=$A12)*('3. Reuniones'!$A$5:$A$64<>"")*'3. Reuniones'!$A$5:$A$64)))) | F12: =IF('2. Ficha'!C70="","",'2. Ficha'!C70) | G12: =IF($A12="","",IF($E12="","Sin reunión",IF(TODAY()-$E12>45,"Sin reunión",IF(AND($F12<>"",$F12<TODAY()),"Revisión vencida",""))))
A13: =IF('2. Ficha'!C75="","",'2. Ficha'!C75) | B13: =IF('2. Ficha'!C76="","",'2. Ficha'!C76) | C13: =IF('2. Ficha'!C77="","",'2. Ficha'!C77) | D13: =IF('2. Ficha'!C78="","",'2. Ficha'!C78) | E13: =IF($A13="","",IF(SUMPRODUCT(MAX(('3. Reuniones'!$B$5:$B$64=$A13)*('3. Reuniones'!$A$5:$A$64<>"")*'3. Reuniones'!$A$5:$A$64))=0,"",SUMPRODUCT(MAX(('3. Reuniones'!$B$5:$B$64=$A13)*('3. Reuniones'!$A$5:$A$64<>"")*'3. Reuniones'!$A$5:$A$64)))) | F13: =IF('2. Ficha'!C80="","",'2. Ficha'!C80) | G13: =IF($A13="","",IF($E13="","Sin reunión",IF(TODAY()-$E13>45,"Sin reunión",IF(AND($F13<>"",$F13<TODAY()),"Revisión vencida",""))))
A15: Categorías con responsable: | B15: =SUMPRODUCT((A6:A13<>"")*(B6:B13<>""))
A16: Categorías sin responsable: | B16: =SUMPRODUCT((A6:A13<>"")*(B6:B13=""))
A18: Avisos: «Sin reunión» si no hay ninguna reunión registrada o han pasado más de 45 días; «Revisión vencida» si la fecha de próxima revisión ya pasó.

Sheet 2. Ficha
A1: FICHA DE CATEGORÍA · UNA POR CATEGORÍA
A2: Amarillo: lo rellenas tú. Azul: se calcula solo con la hoja Reuniones.
A4: Categoría 1
B5: Categoría
B6: Responsable
B7: Objetivo del trimestre (una cifra)
B8: Presupuesto de surtido
B9: Criterio de exposición
B10: Próxima revisión (fecha)
B11: Última decisión tomada | C11: =IF($C$5="","",IFERROR(LOOKUP(2,1/(('3. Reuniones'!$B$5:$B$64=$C$5)*('3. Reuniones'!$A$5:$A$64<>"")),'3. Reuniones'!$G$5:$G$64),""))
B12: Fecha y notas de cada reunión | C12: Se apuntan en la hoja 3. Reuniones: una fila por reunión.
A14: Categoría 2
B15: Categoría
B16: Responsable
B17: Objetivo del trimestre (una cifra)
B18: Presupuesto de surtido
B19: Criterio de exposición
B20: Próxima revisión (fecha)
B21: Última decisión tomada | C21: =IF($C$15="","",IFERROR(LOOKUP(2,1/(('3. Reuniones'!$B$5:$B$64=$C$15)*('3. Reuniones'!$A$5:$A$64<>"")),'3. Reuniones'!$G$5:$G$64),""))
B22: Fecha y notas de cada reunión | C22: Se apuntan en la hoja 3. Reuniones: una fila por reunión.
A24: Categoría 3
B25: Categoría
B26: Responsable
B27: Objetivo del trimestre (una cifra)
B28: Presupuesto de surtido
B29: Criterio de exposición
B30: Próxima revisión (fecha)
B31: Última decisión tomada | C31: =IF($C$25="","",IFERROR(LOOKUP(2,1/(('3. Reuniones'!$B$5:$B$64=$C$25)*('3. Reuniones'!$A$5:$A$64<>"")),'3. Reuniones'!$G$5:$G$64),""))
B32: Fecha y notas de cada reunión | C32: Se apuntan en la hoja 3. Reuniones: una fila por reunión.
A34: Categoría 4
B35: Categoría
B36: Responsable
B37: Objetivo del trimestre (una cifra)
B38: Presupuesto de surtido
B39: Criterio de exposición
B40: Próxima revisión (fecha)
B41: Última decisión tomada | C41: =IF($C$35="","",IFERROR(LOOKUP(2,1/(('3. Reuniones'!$B$5:$B$64=$C$35)*('3. Reuniones'!$A$5:$A$64<>"")),'3. Reuniones'!$G$5:$G$64),""))
B42: Fecha y notas de cada reunión | C42: Se apuntan en la hoja 3. Reuniones: una fila por reunión.
A44: Categoría 5
B45: Categoría
...

Sheet 3. Reuniones
A1: FICHA DE CATEGORÍA · REUNIONES MENSUALES
A2: Una fila por reunión de quince minutos: tres preguntas y una decisión con fecha de revisión.
A4: Fecha | B4: Categoría | C4: Cifra del mes | D4: Qué se cambió desde la última vez | E4: Qué necesita de ti | F4: Fecha de revisión | G4: Decisión (una sola) | H4: Aviso
H5: =IF(AND(A5<>"",G5=""),"Falta la decisión","")
H6: =IF(AND(A6<>"",G6=""),"Falta la decisión","")
H7: =IF(AND(A7<>"",G7=""),"Falta la decisión","")
H8: =IF(AND(A8<>"",G8=""),"Falta la decisión","")
H9: =IF(AND(A9<>"",G9=""),"Falta la decisión","")
H10: =IF(AND(A10<>"",G10=""),"Falta la decisión","")
H11: =IF(AND(A11<>"",G11=""),"Falta la decisión","")
H12: =IF(AND(A12<>"",G12=""),"Falta la decisión","")
H13: =IF(AND(A13<>"",G13=""),"Falta la decisión","")
H14: =IF(AND(A14<>"",G14=""),"Falta la decisión","")
H15: =IF(AND(A15<>"",G15=""),"Falta la decisión","")
H16: =IF(AND(A16<>"",G16=""),"Falta la decisión","")
... H64: =IF(AND(A64<>"",G64=""),"Falta la decisión","")

Sheet 4. Cómo se lee
A1: CÓMO SE LEE LA FICHA
A2: Diez líneas para usarla. Documento interno del titular.
B4: 1. Antes de rellenar nada, decide cuántas categorías vas a repartir: empieza por una o dos, hasta un máximo de ocho.
B5: 2. En la hoja 2 hay una ficha por categoría. Escribe el nombre de la categoría, quién la lleva, el objetivo del trimestre (una sola cifra), el presupuesto de surtido y el criterio de exposición.
B6: 3. El objetivo es una cifra que se pueda sacar del programa de gestión sin una tarde de Excel: unidades, euros, margen o rotación de una gama.
B7: 4. Escribe también la fecha de la próxima revisión. Es la fecha en la que volveréis a mirar la decisión que toméis.
B8: 5. Una vez al mes, en quince minutos y con la categoría delante, apunta la reunión en la hoja 3: la cifra del mes, qué se cambió, qué necesita el responsable de ti y una sola decisión con su fecha de revisión.
B9: 6. Las celdas amarillas las rellenas tú; las azules se calculan solas.
B10: 7. La hoja 1 resume todas las categorías. Si una no tiene responsable, la celda se pone en rojo.
B11: 8. El aviso «Sin reunión» sale si no hay reuniones apuntadas o han pasado más de 45 días desde la última. «Revisión vencida» sale si la fecha de próxima revisión ya pasó.
B12: 9. La última decisión de cada categoría aparece sola en su ficha, tomada de la última reunión apuntada.
B13: 10. Es un documento interno del titular: usa nombres de pila o iniciales si prefieres, y guárdalo como cualquier otro dato del personal.
B15: De dónde sale
B16: Complemento de farmapro Impulso, edición 31: «Cada categoría, un dueño». La guía en PDF explica cómo elegir las categorías, a quién se las das, qué se le pide y cómo es la reunión mensual. Esta ficha es para ir apuntándolo.
... B20: farmapro · farmapro.es
